Workbook

Sheet PENDÊNCIAS
A1: ATIVIDADES | B1: RESPONSÁVEL | C1: PREVISÃO DE TÉRMINO | D1: DIAS ÚTEIS | E1: TEMPO TOTAL | F1: OBSERVAÇÃO | G1: MUST | H1: HOJE | I1: =TODAY() -> 45937 | J1: ANÁLISE MUST | K1: =SUM(G:G) -> 9
A2: Recomendação de 2xBCs ligados (+ máx Ugs sincronizadas) em Cerquilho para Média e Pesada, devido ao risco de subtensão na DIT CTEEP em perda dupla CER-BOT e CER-TOY | B2: Carol | F2: Conversar com o PAR para ver se eles já investigaram este problema
F3: Retirar o requisito de máx UG sincronizada no relatório - OK
A4: Avaliar faixas de reativo do CS Estreito em função das já existentes para os outros CS no Volume 9 | B4: Carol | F4: CS Estreito não tem influência sobre problema de colapso de tensão na malha de 500 kV do SE.
F5: Reavaliar após cálculo dos novos limites de RSUL utilizando tabelas de tempo de falha de comutação de 2024 (cenário Norte Exportador)
A6: Reavaliação da rede complementar | D6: -32812 | E6: -45937 | F6: Verificar: enviar solicitações de saída de equipamentos da rede complementar aos poucos ou no fim de todas as análises?
F7: LTs entre Baguaçu e Três Irmãos
A8: Recomendar desinstalação de SEPs para rede alterada | D8: -32812 | E8: -45937 | F8: TR Mogi Mirim 3, TRs Araraquara, UHE Ilha Solteira
A9: Reavaliar LTs recomendadas para desligamento para controle de tensão | B9: Carol | C9: 5/31/2025 | D9: -92 | E9: -129 | F9: Verificar impactos em função de RSUL
A10: PREOP + Superação NCC com anel São Caetano do Sul | B10: Alexandre/Marcos | C10: 9/30/2025 | D10: -6 | E10: -7 | F10: Andamento das análises de desempenho | G10: 2
A11: Avaliação da perda dupla que causa sobrecarga na transformação 440/138 kV de Bom Jardim por fluxo reativo | B11: Lucas | C11: 9/16/2025 | D11: -16 | E11: -21 | F11: Lucas já avaliou e a Entrada em operação do seccionamento de Fernão dias resolve o problema, faltou avaliarmos com o caso e carga do 1Q2026 | G11: 2
A12: Avaliar a possibilidade de usar a abertura do TR 345/230 kV de Baixada como medida de controle de curto-circuito] | B12: Marcos | C12: 10/20/2025 | D12: 10 | E12: 13 | F12: Avaliar a rede alterada quando todas máquinas despachadas e outras condições. | G12: 5
C13: 45885 | D13: =NETWORKDAYS.INTL(PENDÊNCIAS!$I$1,C13,1) -> -37 | E13: =C13-PENDÊNCIAS!$I$1 -> -52
C14: 45886 | D14: =NETWORKDAYS.INTL(PENDÊNCIAS!$I$1,C14,1) -> -37 | E14: =C14-PENDÊNCIAS!$I$1 -> -51
C15: 45887 | D15: =NETWORKDAYS.INTL(PENDÊNCIAS!$I$1,C15,1) -> -37 | E15: =C15-PENDÊNCIAS!$I$1 -> -50
C16: 45888 | D16: =NETWORKDAYS.INTL(PENDÊNCIAS!$I$1,C16,1) -> -36 | E16: =C16-PENDÊNCIAS!$I$1 -> -49
C17: 45889 | D17: =NETWORKDAYS.INTL(PENDÊNCIAS!$I$1,C17,1) -> -35 | E17: =C17-PENDÊNCIAS!$I$1 -> -48

Sheet CONCLUÍDOS 2025
A1: ATIVIDADES | B1: RESPONSÁVEL | C1: PREVISÃO DE TÉRMINO | D1: DIAS ÚTEIS | E1: TEMPO TOTAL | F1: OBSERVAÇÃO | G1: MUST | H1: HOJE | I1: =TODAY() -> 45937 | J1: ANÁLISE MUST | K1: =SUM(G:G) -> 126
A2: Aumento de MUST em 7 pontos, CPFL Piratininga, SP, SGA-SAM-0128/2024 | B2: Alexandre/Rafaella | C2: 45672 | D2: =NETWORKDAYS.INTL(PENDÊNCIAS!$I$1,C2,1) -> -190 | E2: =C2-PENDÊNCIAS!$I$1 -> -265 | G2: 7
A3: Aumento de MUST no ponto de contratação LUK - 138 kV (A), Elektro, SP, SGA-SAM-0132/2024 | B3: Rafaella | C3: 45684 | D3: =NETWORKDAYS.INTL(PENDÊNCIAS!$I$1,C3,1) -> -182 | E3: =C3-PENDÊNCIAS!$I$1 -> -253 | F3: Aprovado | G3: 1
A4: Aumento de MUST no ponto de contratação EMBRAPORT - 138 kV (A), CPFL Piratininga, SP, SGA-SAM-0133/2024 | B4: Rafaella | C4: 45684 | D4: =NETWORKDAYS.INTL(PENDÊNCIAS!$I$1,C4,1) -> -182 | E4: =C4-PENDÊNCIAS!$I$1 -> -253 | F4: Aprovado com ressalvas | G4: 1
A5: Aumento de MUST em 3 pontos, CPFL Paulista, SP, SGA-SAM-0003/2025 | B5: Alexandre | C5: 45700 | D5: =NETWORKDAYS.INTL(PENDÊNCIAS!$I$1,C5,1) -> -170 | E5: =C5-PENDÊNCIAS!$I$1 -> -237 | F5: pontos devem ficar limitados aos valores da RECON até a entrada do SSSC na LT 138 kV Ribeirão Preto – Porto Ferreira C1/C2, quando os valores solicitados poderão ser liberados, mas sem margem para outros aumentos que impactam nesta LT. Após o SSSC e estes valores de MUST a LT fica em 99/101% de carregamento | G5: 3
A6: MUST flexível no ponto CONPACEL - 138 kV (A), Elektro, SGA-SFX-0002/2025 | B6: Alexandre | C6: 45707 | D6: =NETWORKDAYS.INTL(PENDÊNCIAS!$I$1,C6,1) -> -165 | E6: =C6-PENDÊNCIAS!$I$1 -> -230 | F6: Vale ressaltar que em novembro/2024 a Elektro solicitou acesso flexível para o referido ponto de conexão e nos mesmos montantes apresentados, mas a solicitação foi negada. No momento, não existe CUST Flexível vigente para o referido ponto de contratação. Novamente negado | G6: 1
A7: Carta sobre indisponibilidade do TR1 230/88 kV SE Centro -CTR | B7: Carol | C7: 45709 | D7: =NETWORKDAYS.INTL(PENDÊNCIAS!$I$1,C7,1) -> -163 | E7: =C7-PENDÊNCIAS!$I$1 -> -228 | F7: Carta não emitida - ofício da ANEEL recebido em 24/02/2025
A8: Aumento de MUST no ponto ITATIBA - 138 kV, CPFL Piratininga, SGA-SAM-0007/2025 | B8: Alexandre | C8: 45712 | D8: =NETWORKDAYS.INTL(PENDÊNCIAS!$I$1,C8,1) -> -162 | E8: =C8-PENDÊNCIAS!$I$1 -> -225 | G8: 1
A9: Recomendar no mensal e SysPL desativação dos SEPs de controle de carregamento da LT 138 kV Bariri - Bauru podem ser desinstalados | B9: Rafaella | C9: 45713 | D9: =NETWORKDAYS.INTL(PENDÊNCIAS!$I$1,C9,1) -> -161 | E9: =C9-PENDÊNCIAS!$I$1 -> -224
A10: Recomendar no mensal desativação dos SEPs "ESQUEMA DE BLOQUEIO/DESBLOQUEIO AUTOMÁTICO DOS LTC DA TRANSFORMAÇÃO 345/88 KV DE SUL (1.09.49)" e "ESQUEMA PARA EVITAR SOBRECARGA NA LT 345 KV BAIXADA SANTISTA / TIJUCO PRETO (1.09.19)" após entrada do seccionamento da da LT 345 kV Ibiúna - Tijuco Preto | B10: Rafaella | C10: 45713 | D10: =NETWORKDAYS.INTL(PENDÊNCIAS!$I$1,C10,1) -> -161 | E10: =C10-PENDÊNCIAS!$I$1 -> -224
A11: Aumento de MUST no ponto ZANCHETTA - 138 kV (A), CPFL Piratininga, SGA-SAM-0010/2025 | B11: Alexandre | C11: 45713 | D11: =NETWORKDAYS.INTL(PENDÊNCIAS!$I$1,C11,1) -> -161 | E11: =C11-PENDÊNCIAS!$I$1 -> -224 | G11: 1
A12: Aumento de MUST em 12 pontos de contratação, Elektro Redes, SP, SGA-SAM-0013/2025 | B12: Alexandre | C12: 45714 | D12: =NETWORKDAYS.INTL(PENDÊNCIAS!$I$1,C12,1) -> -160 | E12: =C12-PENDÊNCIAS!$I$1 -> -223 | G12: 12
A13: Aumento de MUST no ponto EDGARD DE SOUZA - 88 kV, ENEL-SP, SGA-SAM-0016/2025, SGA-SAM-0017/2025 e SGA-SAM-0018/2025 | B13: Alexandre | C13: 45721 | D13: =NETWORKDAYS.INTL(PENDÊNCIAS!$I$1,C13,1) -> -155 | E13: =C13-PENDÊNCIAS!$I$1 -> -216 | F13: Data center | G13: 1
A14: NT e carta sobre proposta de realocação do TR da SE Manoel da Nóbrega para a SE Centro -CTR | B14: Carol | C14: 45728 | D14: =NETWORKDAYS.INTL(PENDÊNCIAS!$I$1,C14,1) -> -150 | E14: =C14-PENDÊNCIAS!$I$1 -> -209 | F14: Finalizado
A15: Aumento de MUST no ponto de conexão Da Mata - 138 kV, CPFL Paulista, SP, SGA-SAM-0023/2025 | B15: Carol | C15: 45734 | D15: =NETWORKDAYS.INTL(PENDÊNCIAS!$I$1,C15,1) -> -146 | E15: =C15-PENDÊNCIAS!$I$1 -> -203 | G15: 1
A16: Análise dos impactos da alteração de configuração da rede de distribuição entre Manoel da Nóbrega e Baixada Santista - E-mail Murilo 14/03/2025 | B16: Rafaella | C16: 45737 | D16: =NETWORKDAYS.INTL(PENDÊNCIAS!$I$1,C16,1) -> -143 | E16: =C16-PENDÊNCIAS!$I$1 -> -200 | F16: Diretrizes vigentes já contemplam as consequências.
A17: Alteração de MUST - ELEKTRO - Guariroba 1 138 kV - SP, SGA-SFX-0003/2025 | B17: Alexandre | C17: 45747 | D17: =NETWORKDAYS.INTL(PENDÊNCIAS!$I$1,C17,1) -> -137 | E17: =C17-PENDÊNCIAS!$I$1 -> -190 | G17: 1
A18: Aumento de MUST em 4 pontos de contratação, Elektro Redes, SP, SGA-SAM-0026/2025 | B18: Alexandre | C18: 45748 | D18: =NETWORKDAYS.INTL(PENDÊNCIAS!$I$1,C18,1) -> -136 | E18: =C18-PENDÊNCIAS!$I$1 -> -189 | G18: 4
A19: Avaliar medida operativa/SEP São João da Boa Vista II e impactos na RBF | B19: Carol | C19: 45698 | D19: =NETWORKDAYS.INTL(PENDÊNCIAS!$I$1,C19,1) -> -172 | E19: =C19-PENDÊNCIAS!$I$1 -> -239 | F19: Medida operativa já implantada pela CTEEP, SEP previsto para outubro de 2025 Verificar se SEP será operacionalizado - impactos para o TR 440/138 kV Bom Jardim
A20: Análise da configuração dos barramentos da SE Bariri devido sobrecarga no disjuntor de paralelo - E-mail da Isa Energia 17/03/2025 | B20: Carol | C20: 45733 | D20: =NETWORKDAYS.INTL(PENDÊNCIAS!$I$1,C20,1) -> -147 | E20: =C20-PENDÊNCIAS!$I$1 -> -204 | F20: Encaminhado para EGE
A21: Revisão da NT e carta da proposta de realocação do TR da SE Manoel da Nóbrega para a SE Centro -CTR devido novos dados de carga da Enel | B21: Carol | C21: 45758 | D21: =NETWORKDAYS.INTL(PENDÊNCIAS!$I$1,C21,1) -> -128 | E21: =C21-PENDÊNCIAS!$I$1 -> -179 | F21: OK
A22: Carta de atualização dos dados de remanejamento de carga da Enel e atualização da matriz de diagnóstico | B22: Alexandre | C22: 45755 | D22: =NETWORKDAYS.INTL(PENDÊNCIAS!$I$1,C22,1) -> -131 | E22: =C22-PENDÊNCIAS!$I$1 -> -182 | F22: MUDANÇAS NECESSÁRIAS NA MATRIZ DE DIAGNÓSTICO APÓS CONFIRMAÇÃO DOS DADOS DA ENEL-SP: Atualização de TODAS as cargas atendidas pré-contingência Atualização da carga não atendida pós-contingência: N-2 - LT 345 kV Guarulhos – Norte C1 e C2; N-2 - LT 345 kV Embu Guaçu – Sul e LT 345 kV Sul – Baixada Santista; N-2 - LT 345 kV Leste - Ramon R. Filho C1 e C2; N-1-1 - SE Bandeirantes 345/34,5 kV – 3 x 150 MVA; N-1-1 - SE Centro CTR 230/88 kV – 2 x 250 MVA; N-1-1 - SE Centro CTR 230/20 kV – 2 x 123 + 1 x 135 MVA; N-2 - LT 230 kV Anhanguera – Centro C1 e C2; Mudança da classificação quanto à criticidade no atendimento à carga pós-contingência: N-2 - LT 345 kV Leste - Ramon R. Filho C1 e C2 - do C2 para C3; N-1-1 - SE Centro CTR 230/88 kV – 2 x 250 MVA - do C3 para C2; N-2 - LT 230 kV Anhanguera – Centro C1 e C2 - do C3 para C2; Mudança se tem equipamento reserva: N-1-1 - SE Centro CTR 230/88 kV – 2 x 250 MVA - Retiramos a indicação que havia transformação reserva. MUDANÇAS NECESSÁRIAS QUE NÃO ENVOLVEM OS DADOS DA ENEL-SP Retirar da Matriz de Diagnóstico o N-1-1 da SE Miguel Reale 345/20 kV – 3 x 135 MVA, pois a solução estrutural entrou em operação e o problema de N-1-1 deixa de existir. Aguardar parecer sobre emitissão do revisão do mensal
A23: Reanálise das sobrecargas dos TRs de Jupiá e Bom Jardim em função de não-flexiblização da capacidade pela Isa Energia | B23: Alexandre | D23: =NETWORKDAYS.INTL(PENDÊNCIAS!$I$1,C23,1) -> -32812 | E23: =C23-PENDÊNCIAS!$I$1 -> -45937 | F23: incluídas na revisão 06 do relatório de diretrizes
A24: Reavaliação do SEP de bloqueio do bipolo de Xingu - Estreito quando da perda dos disjuntores de interligação de barras | B24: Carol | D24: =NETWORKDAYS.INTL(PENDÊNCIAS!$I$1,C24,1) -> -32812 | E24: =C24-PENDÊNCIAS!$I$1 -> -45937 | F24: SEP indicado no pré-operacional. Avaliação com limites atuais de RSUL/TVZ 2022 indica a desativação. Reavaliar com novos limites/TVZ atualizado. Estender avaliação ao SEP de runback para sobrecarga quando da perda de apenas um disjuntor. Tratado pela EGE
A25: Colocar no SysPL SEP de TR de Bom Jardim | B25: Alexandre | C25: 45757 | D25: =NETWORKDAYS.INTL(PENDÊNCIAS!$I$1,C25,1) -> -129 | E25: =C25-PENDÊNCIAS!$I$1 -> -180 | F25: URGENTE
A26: Aumento de MUST no ponto de contratação SE Milton Fornasaro 88 kV, ENEL SP, SP, SGA-SAM-0032/2025 | B26: Alexandre | C26: 45761 | D26: =NETWORKDAYS.INTL(PENDÊNCIAS!$I$1,C26,1) -> -127 | E26: =C26-PENDÊNCIAS!$I$1 -> -176 | F26: Milon | G26: 1
A27: Aumento de MUST no ponto de conexão Da Mata - 138 kV, CPFL Paulista, SP, SGA-SAM-0031/2025 | B27: Carol | C27: 45761 | D27: =NETWORKDAYS.INTL(PENDÊNCIAS!$I$1,C27,1) -> -127 | E27: =C27-PENDÊNCIAS!$I$1 -> -176 | F27: Aumento de até 0,2 p.p. na LT 138 kV Três Irmãos - Valparaíso, entre as derivações Andradina e Mirandópolis | G27: 1
A28: Aumento de MUST no ponto de contratação SE Itaí 2 138 kV, CPFL Santa Cruz, SP, SGA-SAM-0030/2025 | B28: Carol | C28: 45761 | D28: =NETWORKDAYS.INTL(PENDÊNCIAS!$I$1,C28,1) -> -127 | E28: =C28-PENDÊNCIAS!$I$1 -> -176 | F28: OK | G28: 1
A29: Aumento de MUST no ponto de contratação Edgard de Souza - 88 kV, ENEL SP, SP, SGA-SPT-0038/2025 - DATA CENTER | B29: Alexandre | C29: 45769 | D29: =NETWORKDAYS.INTL(PENDÊNCIAS!$I$1,C29,1) -> -121 | E29: =C29-PENDÊNCIAS!$I$1 -> -168 | F29: conclusões encaminhadas para o chat plc e plm | G29: 1
A30: Parecer Técnico para Distribuidora ENEL SP - Aumento de MUST no ponto de contratação Edgard de Souza - 88 kV, SP, SGA-SPT-0038/2025 DATA CENTER | C30: 45769 | D30: =NETWORKDAYS.INTL(PENDÊNCIAS!$I$1,C30,1) -> -121 | E30: =C30-PENDÊNCIAS!$I$1 -> -168 | F30: Milon | G30: 1
A31: Parecer Técnico para Distribuidora ENEL SP - Aumento de MUST no ponto de contratação Edgard de Souza - 88 kV, SP, SGA-SPT-0040/2025 DATA CENTER | C31: 45769 | D31: =NETWORKDAYS.INTL(PENDÊNCIAS!$I$1,C31,1) -> -121 | E31: =C31-PENDÊNCIAS!$I$1 -> -168 | F31: Milon | G31: 1
A32: Avaliação de controle de tensão para Norma: abertura da LT440ASS-TAQ | C32: 45763 | D32: =NETWORKDAYS.INTL(PENDÊNCIAS!$I$1,C32,1) -> -125 | E32: =C32-PENDÊNCIAS!$I$1 -> -174 | F32: Verificamos que esta LT ñ é utilizada para esta finalidade há 6 anos, conforme tableau. A restrição existente em capivara (150 MW) é para evitar oscilação na ctg da LT440ASS-CAP
A33: Aumento de MUST Flexível - SE Solvay 440 kV, Unipar Indupa do Brasil, SP, SGA-SFX-0004/2025 | C33: 45775 | D33: =NETWORKDAYS.INTL(PENDÊNCIAS!$I$1,C33,1) -> -117 | E33: =C33-PENDÊNCIAS!$I$1 -> -162 | G33: 1
A34: Aumento dos valores de MUST em 3 pontos de contratação, Elektro Redes, SP, SGA-SAM-0038/2025 | C34: 45775 | D34: =NETWORKDAYS.INTL(PENDÊNCIAS!$I$1,C34,1) -> -117 | E34: =C34-PENDÊNCIAS!$I$1 -> -162 | G34: 3
A35: Aumento dos valores de MUST no ponto Barra Bonita 138 kV, CPFL Paulista, SP, SGA-SAM-0041/2025 | C35: 45775 | D35: =NETWORKDAYS.INTL(PENDÊNCIAS!$I$1,C35,1) -> -117 | E35: =C35-PENDÊNCIAS!$I$1 -> -162 | G35: 1
A36: Parecer de acesso para aumento dos valores de MUST no ponto de contratação UTE Cocal 88 kV, ESS, SP, SGA-SAM-0042/2025 | C36: 45782 | D36: =NETWORKDAYS.INTL(PENDÊNCIAS!$I$1,C36,1) -> -112 | E36: =C36-PENDÊNCIAS!$I$1 -> -155 | G36: 1
A37: Análises das obras do 2Q25 | C37: 45491 | D37: =NETWORKDAYS.INTL(PENDÊNCIAS!$I$1,C37,1) -> -319 | E37: =C37-PENDÊNCIAS!$I$1 -> -446 | F37: - TR1 500/138 kV Água Vermelha - TR5 e TR6 230/88 kV Manoel da Nóbrega?
A38: Avaliação dos impactos da perda do bipolo de Furnas com o remanescente desligado para intervenção de modernização | B38: Carol | C38: 45709 | D38: =NETWORKDAYS.INTL(PENDÊNCIAS!$I$1,C38,1) -> -163 | E38: =C38-PENDÊNCIAS!$I$1 -> -228 | F38: Criado PTC com os impactos da perda de um bipolo. Documento revisado para contemplar a polos conectadas à LTs de bipolos diferentes
A39: Parecer Técnico para Distribuidora - Aumento de MUST no ponto de contratação JANDIRA - 88 kV, ENEL SP, SP, SGA-SPT-0052/2025 - DATA CENTER | B39: Carol | C39: 45803 | D39: =NETWORKDAYS.INTL(PENDÊNCIAS!$I$1,C39,1) -> -97 | E39: =C39-PENDÊNCIAS!$I$1 -> -134 | F39: DATA CENTER | G39: 1
A40: Aumento dos valores de MUST em 4 pontos de contratação, Elektro Redes, SP, SGA-SAM-0050/2025 | B40: Rafaella | C40: 45803 | D40: =NETWORKDAYS.INTL(PENDÊNCIAS!$I$1,C40,1) -> -97 | E40: =C40-PENDÊNCIAS!$I$1 -> -134 | F40: Análise feita e resultados alinhados com o Milon. | G40: 4
...

Sheet CONCLUÍDOS 2024
A1: ATIVIDADES | B1: RESPONSÁVEL | C1: PREVISÃO DE TÉRMINO | D1: DIAS ÚTEIS | E1: TEMPO TOTAL | F1: OBSERVAÇÃO | H1: HOJE
A2: Análise do SEP de Dracena | B2: PLM/PLC (Rafa) | C2: 45329 | D2: =NETWORKDAYS.INTL($H$2,C2,1) -> -435 | E2: =C2-$H$2 -> -608 | F2: Encaminhado em 07/02 | H2: =TODAY() -> 45937
A3: Casos de cenários SP (RSUL, RSE/FSUL, ...) | C3: 45329 | D3: =NETWORKDAYS.INTL($H$2,C3,1) -> -435 | E3: =C3-$H$2 -> -608 | F3: Casos prontos em: https://onsbr.sharepoint.com/:f:/s/soumaisons/EhUtLuDgeYdOkX7daDXqv6oB0IjjeLRiKYl9Q5QCeNSZIg?e=wM1MSy
A4: Carta CTEEP - Desligamento no 345 kV devido obras viárias | C4: 45334 | D4: =NETWORKDAYS.INTL($H$2,C4,1) -> -432 | E4: =C4-$H$2 -> -603 | F4: Encaminhado para Janaína 09/02 Emitida 16/02
A5: Aumento de MUST (SGA-SAM-0004/2024) | B5: PLM/PLC | C5: 45348 | D5: =NETWORKDAYS.INTL($H$2,C5,1) -> -422 | E5: =C5-$H$2 -> -589 | F5: ILHA SOLTEIRA - 138 kV, ITAPEVA 138 kVA, JALES - 138 kV e TRES LAGOAS 1 - 138 kV, no período de maio a dezembro de 2024
A6: Aumento de MUST (SGA-SAM-0006/2024) | B6: PLM/PLC | C6: 45348 | D6: =NETWORKDAYS.INTL($H$2,C6,1) -> -422 | E6: =C6-$H$2 -> -589 | F6: CENTRO - 88 kV e ANHANGUERA - 88 kV, a partir de maio de 2024
A7: SEP de Rosana | B7: PLC | C7: 45338 | D7: =NETWORKDAYS.INTL($H$2,C7,1) -> -428 | E7: =C7-$H$2 -> -599 | F7: Avaliação para alteração da lógica após aumento de capacidade da LT Rosana - Alcídia Comunicado à EGP a inclusão/adequação no mensal - IMPLEMENTADO
A8: Parecer de Acesso Permanente -Revisão - SE UTE BIOPAV 138 kV, SP, SGA-RPA-0012/2024 | B8: Alexandre | C8: 45369 | D8: =NETWORKDAYS.INTL($H$2,C8,1) -> -407 | E8: =C8-$H$2 -> -568 | F8: poderá ser atendida condicionada a conclusão da obra de reconstrução/recondutoramento da LT 138 kV São José do Rio Preto – Catanduva, trecho de 49,3 km de extensão, CD, para capacidade mínima de 206/242 MVA, em condição normal/emergência de operação e obras associadas, autorizadas à ISA CTEEP através da ReA ANEEL nº 12.639/2022, com prazo contratual para 15 de março de 2025 e previstas atualmente pela Transmissora para 13/03/2026
A9: Aumento de MUST TAUBATE - 138 kV (A )- Neoenergia Elektro - SGA-SAM-0012/2024 | B9: Alexandre | C9: 45376 | D9: =NETWORKDAYS.INTL(PENDÊNCIAS!$I$1,C9,1) -> -402 | E9: =C9-PENDÊNCIAS!$I$1 -> -561 | F9: Atual p39/fp40MW
A10: Relatórios 2Q2024 - 440 kV, 345 kV e 500 kV (novo documento) | C10: 45379 | D10: =NETWORKDAYS.INTL(PENDÊNCIAS!$I$1,C10,1) -> -399 | E10: =C10-PENDÊNCIAS!$I$1 -> -558 | F10: incluir análise do C3 ARA-ARA2. Ver NCC em Araraquara OK CPFL ficou de atualizar limite da LT 138 kV São José do Rio Preto (ISA CTEEP) – Mirassol2 na derivação Primavera C1=143/143 e C2=151/151 OK CTEEP precisa atualizar limites das LTs 138 kV Euclides da Cunha - Mococa, Jales - Votuporanga II e São José do Rio Preto - Catanduva (restrição de vão baixo) OK
A11: UTE Univalem - Aumento de Exportação, CPFL Paulista, SP, SGA-SPT-0042/2024 | B11: Alexandre | C11: 45383 | D11: =NETWORKDAYS.INTL(PENDÊNCIAS!$I$1,C11,1) -> -397 | E11: =C11-PENDÊNCIAS!$I$1 -> -554 | F11: Não percebemos problemas nos casos de cenário do Quadrimestral.
A12: Aumento de MUST SUMARE - 138 kV (A) - Atendimento Microsoft CPQ11 - CPFL Paulista, SP, SGA-SAM-0010/2024 | B12: Alexandre | C12: 45383 | D12: =NETWORKDAYS.INTL(PENDÊNCIAS!$I$1,C12,1) -> -397 | E12: =C12-PENDÊNCIAS!$I$1 -> -554 | F12: Aprovado condicionado: fica condicionado a um fator de potência mínimo de 0,95
A13: MUST Flexível - UTE UNIVALEM - 138 kV (A), CPFL Paulista, SP, SGA-SFX-0005/2024 | B13: Alexandre | C13: 45390 | D13: =NETWORKDAYS.INTL(PENDÊNCIAS!$I$1,C13,1) -> -392 | E13: =C13-PENDÊNCIAS!$I$1 -> -547
A14: 1ª Reunião Técnico Gerencial | B14: Carol | C14: 45392 | D14: =NETWORKDAYS.INTL(PENDÊNCIAS!$I$1,C14,1) -> -390 | E14: =C14-PENDÊNCIAS!$I$1 -> -545 | F14: Datas da CTEEP recebidas dia 08/04/2024 e atualizadas no Novo SGIntegração dia 09/04/2024
A15: Modalidade de usina Barra Grande 80 MW em Barra bonita | C15: 45394 | D15: =NETWORKDAYS.INTL(PENDÊNCIAS!$I$1,C15,1) -> -388 | E15: =C15-PENDÊNCIAS!$I$1 -> -543 | F15: Avaliação já realizada e entregue
A16: Aumento de MUST no ponto de contratação Barra Bonita - 138 kV (A) - CPFL Paulista, SP, SGA-SAM-0026/2024 | B16: Alexandre | C16: 45411 | D16: =NETWORKDAYS.INTL(PENDÊNCIAS!$I$1,C16,1) -> -377 | E16: =C16-PENDÊNCIAS!$I$1 -> -526 | F16: passando dos atuais 46,0 MW para 51,0 MW , nos horários de ponta e fora de ponta, de 01 de julho de 2024 a 31 de dezembro de 2025 Documento já elaborado pela PLM
A17: Parecer de Acesso Permanente - CL SE SCALA III, SP, SGA-SPA-0028/2024 | B17: Alexandre | C17: 45404 | D17: =NETWORKDAYS.INTL(PENDÊNCIAS!$I$1,C17,1) -> -382 | E17: =C17-PENDÊNCIAS!$I$1 -> -533
A18: Avaliação do reator de Lorena | F18: Subtensão na perda dupla do 500 kV saindo de Lorena
A19: Aumento de MUST em 3 pontos de contratação - Energisa Sul-Sudeste (ESS), SP, SGA-SAM-0031/2024 | B19: Alexandre | C19: 45406 | D19: =NETWORKDAYS.INTL(PENDÊNCIAS!$I$1,C19,1) -> -380 | E19: =C19-PENDÊNCIAS!$I$1 -> -531
A20: Análise da suspensão da UTE Piratininga | B20: Rafaella | D20: =NETWORKDAYS.INTL(PENDÊNCIAS!$I$1,C20,1) -> -32812 | E20: =C20-PENDÊNCIAS!$I$1 -> -45937 | F20: Revisão da inequação p/ PD Piratininga - Interlagos no TR 345/230 kV BSA Configuração de UGs p/ superação em Henry Borden cobrado à EGP, já entregue e inserido no quadrimestral
A21: Indisponibilidade de um dos trafos de Sul | D21: =NETWORKDAYS.INTL(PENDÊNCIAS!$I$1,C21,1) -> -32812 | E21: =C21-PENDÊNCIAS!$I$1 -> -45937 | F21: Decidido incluir somente menção ao SGI (rev1 do relatório) para avaliações antes da PRI deveremos fazer um parecer técnico
A22: Atualização Planilha Atendimento à Capitais e Radiais Singelos | B22: PLC/PLM | C22: 45401 | D22: =NETWORKDAYS.INTL(PENDÊNCIAS!$I$1,C22,1) -> -383 | E22: =C22-PENDÊNCIAS!$I$1 -> -536 | F22: Entregue versão final, esperando gestores
A23: Aumento de MUST em 13 pontos de contratação - Elektro Redes, SP, SGA-SAM-0034/2024 | B23: Alexandre | C23: 45415 | D23: =NETWORKDAYS.INTL(PENDÊNCIAS!$I$1,C23,1) -> -373 | E23: =C23-PENDÊNCIAS!$I$1 -> -522 | F23: Avaliação já realizada, falta apenas resposta da CTEEP para o ponto "International"
A24: Aumento de MUST em 8 pontos de contratação - CPFL Paulista, SP, SGA-SAM-0028/2024 | B24: Alexandre | C24: 45414 | D24: =NETWORKDAYS.INTL(PENDÊNCIAS!$I$1,C24,1) -> -374 | E24: =C24-PENDÊNCIAS!$I$1 -> -523
A25: Avaliação das perdas duplas que não eram analisadas: LTs 230 kV São José dos Campos – Itapeti e São José dos Campos – Mogi das Cruzes LTs 500 kV Marimbondo II – Araraquara C2 e Marimbondo – Marimbondo II C2 LTs 500 kV Água Vermelha – Marimbondo e Marimbondo – Marimbondo II C3 | B25: Alexandre | D25: =NETWORKDAYS.INTL(PENDÊNCIAS!$I$1,C25,1) -> -32812 | E25: =C25-PENDÊNCIAS!$I$1 -> -45937 | F25: Perda dupla das LTs 230 kV São José dos Campos – Itapeti e São José dos Campos – Mogi das Cruzes: Não foram observados problemas de carregamento ou tensão utilizando os casos de estudo do 2Q2024 Perda dupla das LTs 500 kV Marimbondo II – Araraquara C2 e Marimbondo – Marimbondo II C2: Carregamento: LT 500 kV Marimbondo II - Araraquara C1 pode apresentar carregamento em torno do nominal para o caso de carga Máxima Noturna com RSUL = 12.000 MW; Tensão: Não foram observados problemas de tensão. Perda dupla das LTs 500 kV Água Vermelha – Marimbondo e Marimbondo – Marimbondo II C3: Não foram observados problemas de carregamento ou tensão utilizando os casos de estudo do 2Q2024
A26: Avaliação controle de tensão na região de H.Borden | B26: Alexandre | D26: =NETWORKDAYS.INTL(PENDÊNCIAS!$I$1,C26,1) -> -32812 | E26: =C26-PENDÊNCIAS!$I$1 -> -45937 | F26: Avaliar retirada das informações da IO. CPFL e CTEEP foram questionados sobre as faixas normatizadas para H.Borden 88 e 230 kV. Determinar n° mínimo de Ugs que mantém o controle de tensão adequado Resultados já estão na minuta do Volume 11 revisão 03
A27: BOJ-CAV | D27: =NETWORKDAYS.INTL(PENDÊNCIAS!$I$1,C27,1) -> -32812 | E27: =C27-PENDÊNCIAS!$I$1 -> -45937 | F27: contato com a CTEEP para verificar implementação de abertura automatizada via SAGE E-mail encaminhado 02/05/2024 com informações da sobrecarga. CTEEP informa impossibilidade de flexibilização e não irá implementar automatismo via SAGE, pois há previsão de implementação do SEP
A28: SEP para controle de carregamento em Ibiúna | B28: Alexandre | C28: - | D28: =NETWORKDAYS.INTL(PENDÊNCIAS!$I$1,C28,1) -> #VALUE! | E28: =C28-PENDÊNCIAS!$I$1 -> #VALUE! | F28: Avaliação resultou na impossibilidade de implementação do SEP, pois há violação do 1ºSWG(0,70pu)
A29: Avaliação de desempenho dinâmico da área SP com o "novo" critério de 1ºSWG (0,70pu) | B29: Alexandre | C29: - | D29: =NETWORKDAYS.INTL(PENDÊNCIAS!$I$1,C29,1) -> #VALUE! | E29: =C29-PENDÊNCIAS!$I$1 -> #VALUE! | F29: Foram avaliadas todas contingências de SP e não foram verificadas violações de 1º ou 2º swing
A30: Avaliar questionamentos da Operação: "a dupla de Araraquara/Poços e Araraquara/Campinas não provoca sobrecarga na LT 440 kV Araraquara / Araraquara 2 C1 e C2 por causa do desligamento da Araraquara / Marimbondo II" | B30: Alexandre | D30: =NETWORKDAYS.INTL(PENDÊNCIAS!$I$1,C30,1) -> -32812 | E30: =C30-PENDÊNCIAS!$I$1 -> -45937 | F30: Deverá ser adequado o volume de 500 kV do SECO. Quando da perda dupla citada, sai também a LT 500 kV Araraquara - Marimbondo II C2 por causa do arranjo em anel. A saída desta LT junto com a dupla reduz o carregamento no 440 kV
A31: Avaliar as perdas duplas de SP com atenção ao arranjo das Subestações, para ter certeza que não sai nenhum outro equipamento junto | B31: Alexandre | D31: =NETWORKDAYS.INTL(PENDÊNCIAS!$I$1,C31,1) -> -32812 | E31: =C31-PENDÊNCIAS!$I$1 -> -45937 | F31: Foi necessário alterar os decks de contingências, mas sem consequências necessárias para alterar nos relatórios Contingência Dupla das LTs 230 kV Taubaté – Aparecida C1 e Aparecida – GV do Brasil (LTs em mesma estrutura) LT 230 kV LORENA - APARECIDA C1 FICA EM VAZIO Contingência Dupla da LT 230 kV Aparecida – Lorena (LT em mesma estrutura) LT 230 kV APARECIDA - TAUBATÉ FICA EM VAZIO Contingência Dupla da LT 500 kV Araraquara – Marimbondo 2 (LT em mesma estrutura) LT 500 kV ARARAQUARA - POÇOS FICA EM VAZIO Contingência Dupla das LTs 500 kV Araraquara – Campinas e Araraquara – Poços de Caldas (LTs em mesma estrutura) LT 500 kV ARARAQUARA - MARIMBONDO II C2 FICA EM VAZIO
A32: Aumento de MUST no ponto de contratação Candido Mota - 88 kV (A) - Energisa Sul-Sudeste, SP, SGA-SAM-0043/2024 | B32: Alexandre | C32: 45440 | D32: =NETWORKDAYS.INTL(PENDÊNCIAS!$I$1,C32,1) -> -356 | E32: =C32-PENDÊNCIAS!$I$1 -> -497 | F32: Sem problemas para aumento de MUST. Aguardando revisão do documento pela PLM
A33: Aumento de MUST no ponto de contratação ITATIBA - 138 kV - CPFL Paulista, SP, SGA-SAM-0053/2024 | B33: Alexandre | C33: 45453 | D33: =NETWORKDAYS.INTL(PENDÊNCIAS!$I$1,C33,1) -> -347 | E33: =C33-PENDÊNCIAS!$I$1 -> -484
A34: Aumento de MUST em 4 pontos de contratação - Elektro Redes, SP, SGA-SAM-0046/2024 GUARIROBA 1 - 138 kV (A); AJINOMOTO BIO - 138 kV (A); PETR S ISABEL - 88 kV (A); PETROBRAS ELK - 138 kV (A) | B34: Alexandre | C34: 45446 | D34: =NETWORKDAYS.INTL(PENDÊNCIAS!$I$1,C34,1) -> -352 | E34: =C34-PENDÊNCIAS!$I$1 -> -491
A35: Reavaliar controle de tensão para condição de abertura da EST-FDI e EST-CPA | B35: Carol | F35: Parametrização ok
A36: Avaliação de carregamento C3 LT 440 kV Araraquara - Araraquara 2 com os casos do 3Q24 | B36: Alexandre | D36: =NETWORKDAYS.INTL(PENDÊNCIAS!$I$1,C36,1) -> -32812 | E36: =C36-PENDÊNCIAS!$I$1 -> -45937 | F36: Casos avaliados e nivelados com EGE e EGP, seria necessário runback de 1.500 MW para eliminar sobrecarga inadmissível de 12% caso de máxima noturna com geração interna de SP em 2.500 MW e IPU60 5000 Na hora de planejar o SEP a proprietária do C3 flexibilizou a capacidade do circuito
A37: Aumento de MUST em oito pontos de contratação - Energisa Sul-Sudeste, SP, SGA-SAM-0063/2024 | B37: Rafaella | C37: 45474 | D37: =NETWORKDAYS.INTL(PENDÊNCIAS!$I$1,C37,1) -> -332 | E37: =C37-PENDÊNCIAS!$I$1 -> -463 | F37: Assis I, Bastos, Capivara, Eneida, Itajobi, Palmital, Rancharia e Tupã
A38: Aumento de MUST em 2 pontos de contratação - Elektro Redes, SP, SGA-SAM-0062/2024 | B38: Carol | C38: 45474 | D38: =NETWORKDAYS.INTL(PENDÊNCIAS!$I$1,C38,1) -> -332 | E38: =C38-PENDÊNCIAS!$I$1 -> -463 | F38: D.QUIMICA ELK - 138 kV (A) e HONDA ELK - 138 kV (A)), nos horários de ponta e fora de ponta, a partir de 01 de setembro de 2024 HONDA ELK - 138 kV (A) OK D.QUIMICA ELK - 138 kV (A) OK desconsiderando parcela de confiabilidade da distribuidora
A39: Aumento dos valores de MUST no ponto de Contratação VOTUPORANGA 1 - 138 kV (A) - Elektro Redes, SP, SGA-SAM-0075/2024 | B39: Alexandre | C39: 45495 | D39: =NETWORKDAYS.INTL(PENDÊNCIAS!$I$1,C39,1) -> -317 | E39: =C39-PENDÊNCIAS!$I$1 -> -442 | F39: negado por falta das obras: recap. BOH-JAL-VOT e TR440/138AGV
A40: Aumento dos valores de MUST no ponto de Contratação EMBRAPORT - 138 kV (A) - CPFL Piratininga, SP, SGA-SAM-0067/2024 | B40: Alexandre | C40: 45495 | D40: =NETWORKDAYS.INTL(PENDÊNCIAS!$I$1,C40,1) -> -317 | E40: =C40-PENDÊNCIAS!$I$1 -> -442 | F40: sem restrições: LT 138 kV Baixada - V. Carvalho (159/191) em 70% Mas problemas em regime na LT 138 kV Santo Ângelo - Bertioga II
...
